2023-04-18:22:06:14,869, Starting web crawler...
2023-04-18:22:06:14,869, Crawling: https://www.wtatennis.com/
2023-04-18:22:06:15,216, Finished crawling: https://www.wtatennis.com/
2023-04-18:22:06:15,216, Failed to crawl: https://www.wtatennis.com/
Traceback (most recent call last):
  File "web_crawler.py", line 120, in run_crawler
    time.sleep(0.2)
NameError: name 'time' is not defined
2023-04-18:22:06:15,217, Crawling: apps
2023-04-18:22:06:15,217, Failed to crawl: apps
Traceback (most recent call last):
  File "web_crawler.py", line 116, in run_crawler
    self.crawl_url(url)
  File "web_crawler.py", line 82, in crawl_url
    html = self.get_url_info(url)
  File "web_crawler.py", line 107, in get_url_info
    return requests.get(url).text
  File "/opt/anaconda3/lib/python3.8/site-packages/requests/api.py", line 76, in get
    return request('get', url, params=params, **kwargs)
  File "/opt/anaconda3/lib/python3.8/site-packages/requests/api.py", line 61, in request
    return session.request(method=method, url=url, **kwargs)
  File "/opt/anaconda3/lib/python3.8/site-packages/requests/sessions.py", line 516, in request
    prep = self.prepare_request(req)
  File "/opt/anaconda3/lib/python3.8/site-packages/requests/sessions.py", line 449, in prepare_request
    p.prepare(
  File "/opt/anaconda3/lib/python3.8/site-packages/requests/models.py", line 314, in prepare
    self.prepare_url(url, params)
  File "/opt/anaconda3/lib/python3.8/site-packages/requests/models.py", line 388, in prepare_url
    raise MissingSchema(error)
requests.exceptions.MissingSchema: Invalid URL 'apps': No schema supplied. Perhaps you meant http://apps?
2023-04-18:22:06:15,218, Crawling: http://instagram.com/wta
2023-04-18:22:06:16,361, Finished crawling: http://instagram.com/wta
2023-04-18:22:06:16,361, Failed to crawl: http://instagram.com/wta
Traceback (most recent call last):
  File "web_crawler.py", line 120, in run_crawler
    time.sleep(0.2)
NameError: name 'time' is not defined
2023-04-18:22:06:16,361, Crawling: http://www.usopenseries.com/home/default.sps
2023-04-18:22:06:16,684, Finished crawling: http://www.usopenseries.com/home/default.sps
2023-04-18:22:06:16,684, Failed to crawl: http://www.usopenseries.com/home/default.sps
Traceback (most recent call last):
  File "web_crawler.py", line 120, in run_crawler
    time.sleep(0.2)
NameError: name 'time' is not defined
2023-04-18:22:06:16,684, Crawling: http://t.email.usopen.org/lp/ustaProAcq
2023-04-18:22:06:17,073, Finished crawling: http://t.email.usopen.org/lp/ustaProAcq
2023-04-18:22:06:17,073, Failed to crawl: http://t.email.usopen.org/lp/ustaProAcq
Traceback (most recent call last):
  File "web_crawler.py", line 120, in run_crawler
    time.sleep(0.2)
NameError: name 'time' is not defined
2023-04-18:22:06:17,073, Crawling: http://t.email.usopen.org/lp/ustaProAcq
2023-04-18:22:06:17,073, Finished crawling: http://t.email.usopen.org/lp/ustaProAcq
2023-04-18:22:06:17,074, Failed to crawl: http://t.email.usopen.org/lp/ustaProAcq
Traceback (most recent call last):
  File "web_crawler.py", line 120, in run_crawler
    time.sleep(0.2)
NameError: name 'time' is not defined
2023-04-18:22:06:17,074, Crawling: http://www.atpworldtour.com/
2023-04-18:22:06:17,733, Finished crawling: http://www.atpworldtour.com/
2023-04-18:22:06:17,733, Failed to crawl: http://www.atpworldtour.com/
Traceback (most recent call last):
  File "web_crawler.py", line 120, in run_crawler
    time.sleep(0.2)
NameError: name 'time' is not defined
2023-04-18:22:06:17,733, Crawling: http://
2023-04-18:22:06:17,734, Failed to crawl: http://
Traceback (most recent call last):
  File "web_crawler.py", line 116, in run_crawler
    self.crawl_url(url)
  File "web_crawler.py", line 82, in crawl_url
    html = self.get_url_info(url)
  File "web_crawler.py", line 107, in get_url_info
    return requests.get(url).text
  File "/opt/anaconda3/lib/python3.8/site-packages/requests/api.py", line 76, in get
    return request('get', url, params=params, **kwargs)
  File "/opt/anaconda3/lib/python3.8/site-packages/requests/api.py", line 61, in request
    return session.request(method=method, url=url, **kwargs)
  File "/opt/anaconda3/lib/python3.8/site-packages/requests/sessions.py", line 516, in request
    prep = self.prepare_request(req)
  File "/opt/anaconda3/lib/python3.8/site-packages/requests/sessions.py", line 449, in prepare_request
    p.prepare(
  File "/opt/anaconda3/lib/python3.8/site-packages/requests/models.py", line 314, in prepare
    self.prepare_url(url, params)
  File "/opt/anaconda3/lib/python3.8/site-packages/requests/models.py", line 391, in prepare_url
    raise InvalidURL("Invalid URL %r: No host supplied" % url)
requests.exceptions.InvalidURL: Invalid URL 'http://': No host supplied
2023-04-18:22:06:17,734, Crawling: http://
2023-04-18:22:06:17,734, Finished crawling: http://
2023-04-18:22:06:17,734, Failed to crawl: http://
Traceback (most recent call last):
  File "web_crawler.py", line 120, in run_crawler
    time.sleep(0.2)
NameError: name 'time' is not defined
2023-04-18:22:06:17,734, Crawling: http://
2023-04-18:22:06:17,734, Finished crawling: http://
2023-04-18:22:06:17,734, Failed to crawl: http://
Traceback (most recent call last):
  File "web_crawler.py", line 120, in run_crawler
    time.sleep(0.2)
NameError: name 'time' is not defined
2023-04-18:22:06:17,735, Crawling: http://barcelonaopenbancsabadell.com
2023-04-18:22:06:19,596, Finished crawling: http://barcelonaopenbancsabadell.com
2023-04-18:22:06:19,596, Failed to crawl: http://barcelonaopenbancsabadell.com
Traceback (most recent call last):
  File "web_crawler.py", line 120, in run_crawler
    time.sleep(0.2)
NameError: name 'time' is not defined
2023-04-18:22:06:19,596, Crawling: http://barcelonaopenbancsabadell.com/aviso-legal
2023-04-18:22:06:21,116, Finished crawling: http://barcelonaopenbancsabadell.com/aviso-legal
2023-04-18:22:06:21,116, Failed to crawl: http://barcelonaopenbancsabadell.com/aviso-legal
Traceback (most recent call last):
  File "web_crawler.py", line 120, in run_crawler
    time.sleep(0.2)
NameError: name 'time' is not defined
2023-04-18:22:06:21,116, Crawling: http://barcelonaopenbancsabadell.com/hospitality
2023-04-18:22:06:23,425, Finished crawling: http://barcelonaopenbancsabadell.com/hospitality
2023-04-18:22:06:23,425, Failed to crawl: http://barcelonaopenbancsabadell.com/hospitality
Traceback (most recent call last):
  File "web_crawler.py", line 120, in run_crawler
    time.sleep(0.2)
NameError: name 'time' is not defined
2023-04-18:22:06:23,425, Crawling: http://barcelonaopenbancsabadell.com/noticias
2023-04-18:22:06:27,650, Finished crawling: http://barcelonaopenbancsabadell.com/noticias
2023-04-18:22:06:27,650, Failed to crawl: http://barcelonaopenbancsabadell.com/noticias
Traceback (most recent call last):
  File "web_crawler.py", line 120, in run_crawler
    time.sleep(0.2)
NameError: name 'time' is not defined
2023-04-18:22:06:27,650, Crawling: http://barcelonaopenbancsabadell.com/tickets
2023-04-18:22:06:28,936, Finished crawling: http://barcelonaopenbancsabadell.com/tickets
2023-04-18:22:06:28,937, Failed to crawl: http://barcelonaopenbancsabadell.com/tickets
Traceback (most recent call last):
  File "web_crawler.py", line 120, in run_crawler
    time.sleep(0.2)
NameError: name 'time' is not defined
2023-04-18:22:06:28,937, Crawling: http://https://www.tennisclubroseto.it/atp.html
2023-04-18:22:06:28,952, Failed to crawl: http://https://www.tennisclubroseto.it/atp.html
Traceback (most recent call last):
  File "/opt/anaconda3/lib/python3.8/site-packages/urllib3/connection.py", line 159, in _new_conn
    conn = connection.create_connection(
  File "/opt/anaconda3/lib/python3.8/site-packages/urllib3/util/connection.py", line 61, in create_connection
    for res in socket.getaddrinfo(host, port, family, socket.SOCK_STREAM):
  File "/opt/anaconda3/lib/python3.8/socket.py", line 918, in getaddrinfo
    for res in _socket.getaddrinfo(host, port, family, type, proto, flags):
socket.gaierror: [Errno 8] nodename nor servname provided, or not known

During handling of the above exception, another exception occurred:

Traceback (most recent call last):
  File "/opt/anaconda3/lib/python3.8/site-packages/urllib3/connectionpool.py", line 670, in urlopen
    httplib_response = self._make_request(
  File "/opt/anaconda3/lib/python3.8/site-packages/urllib3/connectionpool.py", line 392, in _make_request
    conn.request(method, url, **httplib_request_kw)
  File "/opt/anaconda3/lib/python3.8/http/client.py", line 1255, in request
    self._send_request(method, url, body, headers, encode_chunked)
  File "/opt/anaconda3/lib/python3.8/http/client.py", line 1301, in _send_request
    self.endheaders(body, encode_chunked=encode_chunked)
  File "/opt/anaconda3/lib/python3.8/http/client.py", line 1250, in endheaders
    self._send_output(message_body, encode_chunked=encode_chunked)
  File "/opt/anaconda3/lib/python3.8/http/client.py", line 1010, in _send_output
    self.send(msg)
  File "/opt/anaconda3/lib/python3.8/http/client.py", line 950, in send
    self.connect()
  File "/opt/anaconda3/lib/python3.8/site-packages/urllib3/connection.py", line 187, in connect
    conn = self._new_conn()
  File "/opt/anaconda3/lib/python3.8/site-packages/urllib3/connection.py", line 171, in _new_conn
    raise NewConnectionError(
urllib3.exceptions.NewConnectionError: <urllib3.connection.HTTPConnection object at 0x7fd809cb4c70>: Failed to establish a new connection: [Errno 8] nodename nor servname provided, or not known

During handling of the above exception, another exception occurred:

Traceback (most recent call last):
  File "/opt/anaconda3/lib/python3.8/site-packages/requests/adapters.py", line 439, in send
    resp = conn.urlopen(
  File "/opt/anaconda3/lib/python3.8/site-packages/urllib3/connectionpool.py", line 726, in urlopen
    retries = retries.increment(
  File "/opt/anaconda3/lib/python3.8/site-packages/urllib3/util/retry.py", line 446, in increment
    raise MaxRetryError(_pool, url, error or ResponseError(cause))
urllib3.exceptions.MaxRetryError: HTTPConnectionPool(host='https', port=80): Max retries exceeded with url: //www.tennisclubroseto.it/atp.html (Caused by NewConnectionError('<urllib3.connection.HTTPConnection object at 0x7fd809cb4c70>: Failed to establish a new connection: [Errno 8] nodename nor servname provided, or not known'))

During handling of the above exception, another exception occurred:

Traceback (most recent call last):
  File "web_crawler.py", line 116, in run_crawler
    self.crawl_url(url)
  File "web_crawler.py", line 82, in crawl_url
    html = self.get_url_info(url)
  File "web_crawler.py", line 107, in get_url_info
    return requests.get(url).text
  File "/opt/anaconda3/lib/python3.8/site-packages/requests/api.py", line 76, in get
    return request('get', url, params=params, **kwargs)
  File "/opt/anaconda3/lib/python3.8/site-packages/requests/api.py", line 61, in request
    return session.request(method=method, url=url, **kwargs)
  File "/opt/anaconda3/lib/python3.8/site-packages/requests/sessions.py", line 530, in request
    resp = self.send(prep, **send_kwargs)
  File "/opt/anaconda3/lib/python3.8/site-packages/requests/sessions.py", line 643, in send
    r = adapter.send(request, **kwargs)
  File "/opt/anaconda3/lib/python3.8/site-packages/requests/adapters.py", line 516, in send
    raise ConnectionError(e, request=request)
requests.exceptions.ConnectionError: HTTPConnectionPool(host='https', port=80): Max retries exceeded with url: //www.tennisclubroseto.it/atp.html (Caused by NewConnectionError('<urllib3.connection.HTTPConnection object at 0x7fd809cb4c70>: Failed to establish a new connection: [Errno 8] nodename nor servname provided, or not known'))
2023-04-18:22:06:28,954, Crawling: http://oeirasopen.pt/home
2023-04-18:22:06:30,311, Finished crawling: http://oeirasopen.pt/home
2023-04-18:22:06:30,311, Failed to crawl: http://oeirasopen.pt/home
Traceback (most recent call last):
  File "web_crawler.py", line 120, in run_crawler
    time.sleep(0.2)
NameError: name 'time' is not defined
2023-04-18:22:06:30,311, Crawling: http://oeirasopen.pt/comochegar
2023-04-18:22:06:30,774, Finished crawling: http://oeirasopen.pt/comochegar
2023-04-18:22:06:30,774, Failed to crawl: http://oeirasopen.pt/comochegar
Traceback (most recent call last):
  File "web_crawler.py", line 120, in run_crawler
    time.sleep(0.2)
NameError: name 'time' is not defined
2023-04-18:22:06:30,774, Crawling: http://oeirasopen.pt/home/conferencias
