2023-04-18:22:04:45,619, Starting web crawler...
2023-04-18:22:04:45,619, Crawling: https://www.wtatennis.com/
2023-04-18:22:04:45,975, Finished crawling: https://www.wtatennis.com/
2023-04-18:22:04:45,976, Failed to crawl: https://www.wtatennis.com/
Traceback (most recent call last):
  File "web_crawler.py", line 118, in run_crawler
    time.sleep(0.2)
NameError: name 'time' is not defined
2023-04-18:22:04:45,976, Crawling: apps
2023-04-18:22:04:45,976, Failed to crawl: apps
Traceback (most recent call last):
  File "web_crawler.py", line 114, in run_crawler
    self.crawl_url(url)
  File "web_crawler.py", line 80, in crawl_url
    html = self.get_url_info(url)
  File "web_crawler.py", line 105, in get_url_info
    return requests.get(url).text
  File "/opt/anaconda3/lib/python3.8/site-packages/requests/api.py", line 76, in get
    return request('get', url, params=params, **kwargs)
  File "/opt/anaconda3/lib/python3.8/site-packages/requests/api.py", line 61, in request
    return session.request(method=method, url=url, **kwargs)
  File "/opt/anaconda3/lib/python3.8/site-packages/requests/sessions.py", line 516, in request
    prep = self.prepare_request(req)
  File "/opt/anaconda3/lib/python3.8/site-packages/requests/sessions.py", line 449, in prepare_request
    p.prepare(
  File "/opt/anaconda3/lib/python3.8/site-packages/requests/models.py", line 314, in prepare
    self.prepare_url(url, params)
  File "/opt/anaconda3/lib/python3.8/site-packages/requests/models.py", line 388, in prepare_url
    raise MissingSchema(error)
requests.exceptions.MissingSchema: Invalid URL 'apps': No schema supplied. Perhaps you meant http://apps?
2023-04-18:22:04:45,978, Crawling: http://instagram.com/wta
2023-04-18:22:04:46,988, Finished crawling: http://instagram.com/wta
2023-04-18:22:04:46,988, Failed to crawl: http://instagram.com/wta
Traceback (most recent call last):
  File "web_crawler.py", line 118, in run_crawler
    time.sleep(0.2)
NameError: name 'time' is not defined
2023-04-18:22:04:46,989, Crawling: http://www.usopenseries.com/home/default.sps
2023-04-18:22:04:47,567, Finished crawling: http://www.usopenseries.com/home/default.sps
2023-04-18:22:04:47,567, Failed to crawl: http://www.usopenseries.com/home/default.sps
Traceback (most recent call last):
  File "web_crawler.py", line 118, in run_crawler
    time.sleep(0.2)
NameError: name 'time' is not defined
2023-04-18:22:04:47,568, Crawling: http://t.email.usopen.org/lp/ustaProAcq
2023-04-18:22:04:47,980, Finished crawling: http://t.email.usopen.org/lp/ustaProAcq
2023-04-18:22:04:47,980, Failed to crawl: http://t.email.usopen.org/lp/ustaProAcq
Traceback (most recent call last):
  File "web_crawler.py", line 118, in run_crawler
    time.sleep(0.2)
NameError: name 'time' is not defined
2023-04-18:22:04:47,981, Crawling: http://t.email.usopen.org/lp/ustaProAcq
2023-04-18:22:04:47,981, Finished crawling: http://t.email.usopen.org/lp/ustaProAcq
2023-04-18:22:04:47,981, Failed to crawl: http://t.email.usopen.org/lp/ustaProAcq
Traceback (most recent call last):
  File "web_crawler.py", line 118, in run_crawler
    time.sleep(0.2)
NameError: name 'time' is not defined
2023-04-18:22:04:47,981, Crawling: http://www.atpworldtour.com/
2023-04-18:22:04:48,873, Finished crawling: http://www.atpworldtour.com/
2023-04-18:22:04:48,873, Failed to crawl: http://www.atpworldtour.com/
Traceback (most recent call last):
  File "web_crawler.py", line 118, in run_crawler
    time.sleep(0.2)
NameError: name 'time' is not defined
2023-04-18:22:04:48,873, Crawling: http://
2023-04-18:22:04:48,874, Failed to crawl: http://
Traceback (most recent call last):
  File "web_crawler.py", line 114, in run_crawler
    self.crawl_url(url)
  File "web_crawler.py", line 80, in crawl_url
    html = self.get_url_info(url)
  File "web_crawler.py", line 105, in get_url_info
    return requests.get(url).text
  File "/opt/anaconda3/lib/python3.8/site-packages/requests/api.py", line 76, in get
    return request('get', url, params=params, **kwargs)
  File "/opt/anaconda3/lib/python3.8/site-packages/requests/api.py", line 61, in request
    return session.request(method=method, url=url, **kwargs)
  File "/opt/anaconda3/lib/python3.8/site-packages/requests/sessions.py", line 516, in request
    prep = self.prepare_request(req)
  File "/opt/anaconda3/lib/python3.8/site-packages/requests/sessions.py", line 449, in prepare_request
    p.prepare(
  File "/opt/anaconda3/lib/python3.8/site-packages/requests/models.py", line 314, in prepare
    self.prepare_url(url, params)
  File "/opt/anaconda3/lib/python3.8/site-packages/requests/models.py", line 391, in prepare_url
    raise InvalidURL("Invalid URL %r: No host supplied" % url)
requests.exceptions.InvalidURL: Invalid URL 'http://': No host supplied
2023-04-18:22:04:48,874, Crawling: http://
2023-04-18:22:04:48,874, Failed to crawl: http://
Traceback (most recent call last):
  File "web_crawler.py", line 114, in run_crawler
    self.crawl_url(url)
  File "web_crawler.py", line 80, in crawl_url
    html = self.get_url_info(url)
  File "web_crawler.py", line 105, in get_url_info
    return requests.get(url).text
  File "/opt/anaconda3/lib/python3.8/site-packages/requests/api.py", line 76, in get
    return request('get', url, params=params, **kwargs)
  File "/opt/anaconda3/lib/python3.8/site-packages/requests/api.py", line 61, in request
    return session.request(method=method, url=url, **kwargs)
  File "/opt/anaconda3/lib/python3.8/site-packages/requests/sessions.py", line 516, in request
    prep = self.prepare_request(req)
  File "/opt/anaconda3/lib/python3.8/site-packages/requests/sessions.py", line 449, in prepare_request
    p.prepare(
  File "/opt/anaconda3/lib/python3.8/site-packages/requests/models.py", line 314, in prepare
    self.prepare_url(url, params)
  File "/opt/anaconda3/lib/python3.8/site-packages/requests/models.py", line 391, in prepare_url
    raise InvalidURL("Invalid URL %r: No host supplied" % url)
requests.exceptions.InvalidURL: Invalid URL 'http://': No host supplied
2023-04-18:22:04:48,875, Crawling: http://
2023-04-18:22:04:48,875, Failed to crawl: http://
Traceback (most recent call last):
  File "web_crawler.py", line 114, in run_crawler
    self.crawl_url(url)
  File "web_crawler.py", line 80, in crawl_url
    html = self.get_url_info(url)
  File "web_crawler.py", line 105, in get_url_info
    return requests.get(url).text
  File "/opt/anaconda3/lib/python3.8/site-packages/requests/api.py", line 76, in get
    return request('get', url, params=params, **kwargs)
  File "/opt/anaconda3/lib/python3.8/site-packages/requests/api.py", line 61, in request
    return session.request(method=method, url=url, **kwargs)
  File "/opt/anaconda3/lib/python3.8/site-packages/requests/sessions.py", line 516, in request
    prep = self.prepare_request(req)
  File "/opt/anaconda3/lib/python3.8/site-packages/requests/sessions.py", line 449, in prepare_request
    p.prepare(
  File "/opt/anaconda3/lib/python3.8/site-packages/requests/models.py", line 314, in prepare
    self.prepare_url(url, params)
  File "/opt/anaconda3/lib/python3.8/site-packages/requests/models.py", line 391, in prepare_url
    raise InvalidURL("Invalid URL %r: No host supplied" % url)
requests.exceptions.InvalidURL: Invalid URL 'http://': No host supplied
2023-04-18:22:04:48,875, Crawling: http://barcelonaopenbancsabadell.com
2023-04-18:22:04:50,512, Finished crawling: http://barcelonaopenbancsabadell.com
2023-04-18:22:04:50,513, Failed to crawl: http://barcelonaopenbancsabadell.com
Traceback (most recent call last):
  File "web_crawler.py", line 118, in run_crawler
    time.sleep(0.2)
NameError: name 'time' is not defined
2023-04-18:22:04:50,513, Crawling: http://barcelonaopenbancsabadell.com/aviso-legal
2023-04-18:22:04:51,540, Finished crawling: http://barcelonaopenbancsabadell.com/aviso-legal
2023-04-18:22:04:51,540, Failed to crawl: http://barcelonaopenbancsabadell.com/aviso-legal
Traceback (most recent call last):
  File "web_crawler.py", line 118, in run_crawler
    time.sleep(0.2)
NameError: name 'time' is not defined
2023-04-18:22:04:51,540, Crawling: http://barcelonaopenbancsabadell.com/aviso-legal
2023-04-18:22:04:51,540, Finished crawling: http://barcelonaopenbancsabadell.com/aviso-legal
2023-04-18:22:04:51,540, Failed to crawl: http://barcelonaopenbancsabadell.com/aviso-legal
Traceback (most recent call last):
  File "web_crawler.py", line 118, in run_crawler
    time.sleep(0.2)
NameError: name 'time' is not defined
2023-04-18:22:04:51,540, Crawling: http://barcelonaopenbancsabadell.com/hospitality
2023-04-18:22:04:52,779, Finished crawling: http://barcelonaopenbancsabadell.com/hospitality
2023-04-18:22:04:52,779, Failed to crawl: http://barcelonaopenbancsabadell.com/hospitality
Traceback (most recent call last):
  File "web_crawler.py", line 118, in run_crawler
    time.sleep(0.2)
NameError: name 'time' is not defined
2023-04-18:22:04:52,779, Crawling: http://barcelonaopenbancsabadell.com/noticias
2023-04-18:22:04:55,801, Finished crawling: http://barcelonaopenbancsabadell.com/noticias
2023-04-18:22:04:55,801, Failed to crawl: http://barcelonaopenbancsabadell.com/noticias
Traceback (most recent call last):
  File "web_crawler.py", line 118, in run_crawler
    time.sleep(0.2)
NameError: name 'time' is not defined
2023-04-18:22:04:55,801, Crawling: http://barcelonaopenbancsabadell.com/tickets
